<?xml version="1.0"?>
<robot name="my_robot">
  <!-- Base link (box) -->
  <link name="base_link">
    <visual>
      <origin xyz="0.0 0.0 0.0" rpy="0.0 0.0 0.0"/>
      <geometry>
        <box size="0.05 0.05 0.3"/>
      </geometry>
      <material name="">
        <color rgba="1.0 0.70 0.0 1.0"/>
        <texture filename=""/>
      </material>
    </visual>
    <collision>
      <origin xyz="0.0 0.0 0.0" rpy="0.0 0.0 0.0"/>
      <geometry>
        <box size="0.05 0.05 0.3"/>
      </geometry>
    </collision>
    <inertial>
      <mass value="1.0"/>
      <origin xyz="0 0 0" rpy="0 0 0"/>
      <inertia ixx="0.0079167" ixy="0" ixz="0" iyy="0.0079167" iyz="0" izz="0.0004167"/>
    </inertial>
  </link>

  <link name="child_link">
    <visual>
      <origin xyz="0.0 0.0 0.08" rpy="0.0 0.0 0.0"/>
      <geometry>
        <box size="0.02 0.05 0.2"/>
      </geometry>
      <material name="">
        <color rgba="1.0 0.0 0.0 1.0"/>
        <texture filename=""/>
      </material>
    </visual>
    <collision>
      <origin xyz="0.0 0.0 0.08" rpy="0.0 0.0 0.0"/>
      <geometry>
        <box size="0.02 0.05 0.2"/>
      </geometry>
    </collision>
    <inertial>
      <mass value="0.02"/>
      <origin xyz="0.0 0.0 0.08" rpy="0 0 0"/>
      <inertia ixx="5.6333e-5" ixy="0" ixz="0" iyy="6.8000e-5" iyz="0" izz="3.3333e-6"/>
    </inertial>
  </link>

  <joint name="revolute_joint" type="revolute">
    <parent link="base_link"/>
    <child link="child_link"/>
    <origin xyz="0.035 0.0 0.15" rpy="0.0 0.0 0.0"/>
    <axis xyz="1 0.0 0.0"/>
    <limit lower="-0.523599" upper="0.523599" effort="0.0" velocity="0.0"/>  
  </joint>

  
</robot>